Workbook
Name metric_np: '披露数据'!$B$5
Name metric_da: '披露数据'!$B$6
Name metric_interest: '披露数据'!$B$7
Name metric_tax: '披露数据'!$B$8
Name metric_ebitda_control: '披露数据'!$B$9
Name metric_wc: '披露数据'!$B$10
Name metric_other: '披露数据'!$B$11
Name metric_capex: '披露数据'!$B$12
Name metric_principal: '披露数据'!$B$13
Name metric_cash_interest_tax: '披露数据'!$B$14
Name metric_old_reserve: '披露数据'!$B$15
Name metric_d_control: '披露数据'!$B$16
Name metric_revenue: '披露数据'!$B$17
Name metric_project_ebitda: '披露数据'!$B$18
Name metric_cash_in: '披露数据'!$B$19
Name metric_cash_out: '披露数据'!$B$20
Name metric_cash_control: '披露数据'!$B$21
Name metric_fund_cash: '披露数据'!$B$22
Name metric_fund_income: '披露数据'!$B$23
Name metric_shares: '披露数据'!$B$24
Name metric_actual_paid: '披露数据'!$B$25
Name metric_ratio: '披露数据'!$B$26
Name metric_management_fee: '披露数据'!$B$27
Name metric_custody_fee: '披露数据'!$B$28
Name metric_operator_fee: '披露数据'!$B$29
Name metric_selector: '分配模型'!$B$4
Name metric_custom_decline: '分配模型'!$B$23
Name metric_custom_reserve: '分配模型'!$B$27
Name metric_proposed_input: '分配模型'!$B$28
Name metric_D: '分配模型'!$B$6
Name metric_lower: '分配模型'!$B$7
Name metric_upper: '分配模型'!$B$8
Name metric_positive: '分配模型'!$B$8
Name metric_per_unit: '分配模型'!$B$9
Name metric_proposed: '分配模型'!$B$10
Name metric_upper_margin: '分配模型'!$B$11
Name metric_lower_margin: '分配模型'!$B$12
Name metric_decision: '分配模型'!$B$13
Name metric_budget: '分配模型'!$B$14
Name metric_remaining: '分配模型'!$B$15
Name metric_historical: '分配模型'!$B$53
Name metric_ebitda: '分配模型'!$B$45
Name metric_pre_reserve: '分配模型'!$B$51
Name metric_project_cash: '分配模型'!$B$58
Name metric_scope_difference: '分配模型'!$B$60
Name metric_historical_per_unit: '分配模型'!$B$61
Name metric_ebitda_variance: '分配模型'!$B$56
Name metric_d_variance: '分配模型'!$B$57
Name metric_cash_variance: '分配模型'!$B$59
Name metric_sensitivity_D_d00_r0: '敏感性'!$C$7
Name metric_sensitivity_margin_d00_r0: '敏感性'!$C$16
Name metric_sensitivity_D_d00_r500: '敏感性'!$D$7
Name metric_sensitivity_margin_d00_r500: '敏感性'!$D$16
Name metric_sensitivity_D_d00_r1000: '敏感性'!$E$7
Name metric_sensitivity_margin_d00_r1000: '敏感性'!$E$16
Name metric_sensitivity_D_d05_r0: '敏感性'!$C$8
Name metric_sensitivity_margin_d05_r0: '敏感性'!$C$17
Name metric_sensitivity_D_d05_r500: '敏感性'!$D$8
Name metric_sensitivity_margin_d05_r500: '敏感性'!$D$17
Name metric_sensitivity_D_d05_r1000: '敏感性'!$E$8

Sheet 分配模型
A2: 万国数据中心 REIT 分配模型
A3: 人民币元；2025 披露基础与分配测算
A4: 情景选择 | B4: 1 | C4: =IF(AND(ISNUMBER(B4),B4>=1,B4<=3,B4=INT(B4)),CHOOSE(B4,"基准","压力","自定义"),"输入不可用")
A5: 活动结果 | B5: 金额 / 状态 | C5: 说明
A6: 情景可供分配金额 D | B6: =B37 | C6: 已扣原预留；新增预留再扣一次
A7: 90% 分配下限 | B7: =IF(ISNUMBER(B6),MAX(B6,0)*'披露数据'!B26,"n.a.") | C7: 年度方案前提详见财务测算参数
A8: 100% 分配上限 | B8: =IF(ISNUMBER(B6),MAX(B6,0),"n.a.") | C8: 负 D 保留风险信息，上限取零
A9: 正向可供分配每份金额 | B9: =IF(ISNUMBER(B8),B8/'披露数据'!B24,"n.a.") | C9: 元 / 份；分母为 8 亿份
A10: 拟分配额 | B10: =IF(ISBLANK(B28),"n.a.",IF(AND(ISNUMBER(B28),B28>=0),B28,"n.a."))
A11: 对上限余量 | B11: =IF(AND(ISNUMBER(B8),ISNUMBER(B10)),B8-B10,"n.a.") | C11: 负数表示拟分配超上限
A12: 对下限余量 | B12: =IF(AND(ISNUMBER(B10),ISNUMBER(B7)),B10-B7,"n.a.") | C12: 负数表示拟分配低于下限
A13: 拟分配结论 | B13: =IF(AND(ISNUMBER(B6),ISNUMBER(B10)),IF(B6<=0,"无正向分配空间",IF(B10<B7,"低于下限",IF(B10>B8,"超过上限","区间内"))),"输入不可用")
A14: 最大新增预留预算 | B14: =IF(AND(ISNUMBER(B36),ISNUMBER(B10)),B53-B36-B10,"n.a.") | C14: 只测试上限；负数表示目标不可达
A15: 当前新增预留后剩余预算 | B15: =IF(AND(ISNUMBER(B14),ISNUMBER(B35)),B14-B35,"n.a.") | C15: 当前额外预留之外的剩余空间
A18: 情景参数 | B18: 输入 / 活动值 | C18: 1 基准 2 压力 3 自定义
A19: 输入标记 | B19: 黄色为可编辑 | C19: 基准和压力采用 scenario.json 参数
A20: 活动收入下降率 | B20: =IF(AND(ISNUMBER($B$4),$B$4>=1,$B$4<=3,$B$4=INT($B$4)),IF(CHOOSE($B$4,ISBLANK(B21),ISBLANK(B22),ISBLANK(B23)),"输入不可用",IF(AND(ISNUMBER(CHOOSE($B$4,B21,B22,B23)),CHOOSE($B$4,B21,B22,B23)>=0,CHOOSE($B$4,B21,B22,B23)<=1),CHOOSE($B$4,B21,B22,B23),"输入不可用")),"输入不可用")
A21: 基准收入下降率 | B21: 0
A22: 压力收入下降率 | B22: 0.1
A23: 自定义收入下降率 | B23: 0.2 | C23: 可编辑；下降率0至100%
A24: 活动新增预留 | B24: =IF(AND(ISNUMBER($B$4),$B$4>=1,$B$4<=3,$B$4=INT($B$4)),IF(CHOOSE($B$4,ISBLANK(B25),ISBLANK(B26),ISBLANK(B27)),"输入不可用",IF(AND(ISNUMBER(CHOOSE($B$4,B25,B26,B27)),CHOOSE($B$4,B25,B26,B27)>=0),CHOOSE($B$4,B25,B26,B27),"输入不可用")),"输入不可用")
A25: 基准新增预留 | B25: 0
A26: 压力新增预留 | B26: 5000000
A27: 自定义新增预留 | B27: 10000000 | C27: 可编辑；新增预留为非负数
A28: 拟分配额输入 | B28: 85000000
A31: 活动计算链 | B31: 金额 / 比率 | C31: 历史事实不随选择器变化
A32: 历史可供分配锚点 | B32: =B53
A33: 项目公司营业收入驱动 | B33: ='披露数据'!B17 | C33: 项目营业收入用于增量测算
A34: 活动收入下降率链接 | B34: =B20
A35: 活动新增预留链接 | B35: =B24
A36: 收入损失 | B36: =IF(ISNUMBER(B34),B33*B34,"收入输入不可用")
A37: 扣收入损失及新增预留后 D | B37: =IF(AND(ISNUMBER(B36),ISNUMBER(B35)),B32-B36-B35,"情景输入不可用")
A40: 2025 披露历史桥接 | B40: 人民币元 | C40: 2025-07-18 至 2025-12-31
A41: 合并净利润 | B41: ='披露数据'!B5
A42: 加回折旧和摊销 | B42: ='披露数据'!B6
A43: 加回利息支出 | B43: ='披露数据'!B7
A44: 加回所得税费用 | B44: ='披露数据'!B8
A45: 复算基金 EBITDA | B45: =SUM(B41:B44)
A46: 应收和应付项目变动 | B46: ='披露数据'!B10
A47: 其他调增项 | B47: ='披露数据'!B11 | C47: 含发行、处置、金融资产及期初现金等
...

Sheet 敏感性
A2: 收入下滑及新增预留敏感性
B3: 当前情景 | C3: ='分配模型'!C4
B4: 人民币元；显式公式矩阵
B5: 情景可供分配金额 D
B6: 收入下降率 / 新增预留 | C6: 0 | D6: 5000000 | E6: 10000000
B7: 0 | C7: ='分配模型'!$B$53-'披露数据'!$B$17*$B7-C$6 | D7: ='分配模型'!$B$53-'披露数据'!$B$17*$B7-D$6 | E7: ='分配模型'!$B$53-'披露数据'!$B$17*$B7-E$6
B8: 0.05 | C8: ='分配模型'!$B$53-'披露数据'!$B$17*$B8-C$6 | D8: ='分配模型'!$B$53-'披露数据'!$B$17*$B8-D$6 | E8: ='分配模型'!$B$53-'披露数据'!$B$17*$B8-E$6
B9: 0.1 | C9: ='分配模型'!$B$53-'披露数据'!$B$17*$B9-C$6 | D9: ='分配模型'!$B$53-'披露数据'!$B$17*$B9-D$6 | E9: ='分配模型'!$B$53-'披露数据'!$B$17*$B9-E$6
B10: 0.15 | C10: ='分配模型'!$B$53-'披露数据'!$B$17*$B10-C$6 | D10: ='分配模型'!$B$53-'披露数据'!$B$17*$B10-D$6 | E10: ='分配模型'!$B$53-'披露数据'!$B$17*$B10-E$6
B11: 0.2 | C11: ='分配模型'!$B$53-'披露数据'!$B$17*$B11-C$6 | D11: ='分配模型'!$B$53-'披露数据'!$B$17*$B11-D$6 | E11: ='分配模型'!$B$53-'披露数据'!$B$17*$B11-E$6
B14: 拟分配相对100%上限余量
B15: 收入下降率 / 新增预留 | C15: =C6 | D15: =D6 | E15: =E6
B16: =B7 | C16: =IF(ISNUMBER('分配模型'!$B$10),MAX(C7,0)-'分配模型'!$B$10,"n.a.") | D16: =IF(ISNUMBER('分配模型'!$B$10),MAX(D7,0)-'分配模型'!$B$10,"n.a.") | E16: =IF(ISNUMBER('分配模型'!$B$10),MAX(E7,0)-'分配模型'!$B$10,"n.a.")
B17: =B8 | C17: =IF(ISNUMBER('分配模型'!$B$10),MAX(C8,0)-'分配模型'!$B$10,"n.a.") | D17: =IF(ISNUMBER('分配模型'!$B$10),MAX(D8,0)-'分配模型'!$B$10,"n.a.") | E17: =IF(ISNUMBER('分配模型'!$B$10),MAX(E8,0)-'分配模型'!$B$10,"n.a.")
B18: =B9 | C18: =IF(ISNUMBER('分配模型'!$B$10),MAX(C9,0)-'分配模型'!$B$10,"n.a.") | D18: =IF(ISNUMBER('分配模型'!$B$10),MAX(D9,0)-'分配模型'!$B$10,"n.a.") | E18: =IF(ISNUMBER('分配模型'!$B$10),MAX(E9,0)-'分配模型'!$B$10,"n.a.")
B19: =B10 | C19: =IF(ISNUMBER('分配模型'!$B$10),MAX(C10,0)-'分配模型'!$B$10,"n.a.") | D19: =IF(ISNUMBER('分配模型'!$B$10),MAX(D10,0)-'分配模型'!$B$10,"n.a.") | E19: =IF(ISNUMBER('分配模型'!$B$10),MAX(E10,0)-'分配模型'!$B$10,"n.a.")
B20: =B11 | C20: =IF(ISNUMBER('分配模型'!$B$10),MAX(C11,0)-'分配模型'!$B$10,"n.a.") | D20: =IF(ISNUMBER('分配模型'!$B$10),MAX(D11,0)-'分配模型'!$B$10,"n.a.") | E20: =IF(ISNUMBER('分配模型'!$B$10),MAX(E11,0)-'分配模型'!$B$10,"n.a.")
B22: 基准点 C7；压力点 D9
B23: 余量<0 表示拟分配超过上限

Sheet 披露数据
A2: 2025 年报披露数据
A3: 来源 F025 2025年报；物理页=PDF页，印刷页=物理页−1
A4: 披露指标 | B4: 数值（人民币元） | C4: 范围 | D4: 物理页 / 印刷页 | E4: 章节
A5: 合并净利润 | B5: 23280784 | C5: fund-consolidated | D5: 10 / 9 | E5: 3.3.2.1
A6: 折旧和摊销 | B6: 41849395 | C6: fund-consolidated | D6: 10 / 9 | E6: 3.3.2.1
A7: 利息支出 | B7: 3427256 | C7: fund-consolidated | D7: 10 / 9 | E7: 3.3.2.1
A8: 所得税费用 | B8: 4242395 | C8: fund-consolidated | D8: 10 / 9 | E8: 3.3.2.1
A9: 披露基金EBITDA | B9: 72799830 | C9: fund-consolidated | D9: 10 / 9 | E9: 3.3.2.1
A10: 应收和应付项目变动 | B10: 60480597 | C10: fund-consolidated | D10: 10 / 9 | E10: 3.3.2.1
A11: 其他调增项 | B11: 2.3909882e+09 | C11: fund-consolidated | D11: 10 / 9 | E11: 3.3.2.1
A12: 购买不动产等资本性支出 | B12: -2.1863823e+09 | C12: fund-consolidated | D12: 10 / 9 | E12: 3.3.2.1
A13: 偿还借款本金 | B13: -200000000 | C13: fund-consolidated | D13: 10 / 9 | E13: 3.3.2.1
A14: 支付利息及所得税 | B14: -7104333.3 | C14: fund-consolidated | D14: 10 / 9 | E14: 3.3.2.1
A15: 未来合理相关支出预留 | B15: -38723544 | C15: fund-consolidated | D15: 10 / 9 | E15: 3.3.2.1
A16: 披露可供分配金额 | B16: 92058482 | C16: fund-consolidated | D16: 10 / 9 | E16: 3.3.1.1及3.3.2.1
... A29: 本期计提运营管理费 | B29: 9964029.1 | C29: project-company | D29: 11 / 10 | E29: 3.4.1
A31: 合同生效日 2025-07-18；期末 2025-12-31
A32: 预留已扣，3.4.1本期计提费用已扣
A33: 过渡期损益自2025-03-31归投资人；3.3.2.1注2
A34: 报告期非完整年度；原件未披露预留用途分项金额
